Workbook

Sheet Como usar
A1: Campo | B1: Orientação
A2: Plano | B2: 100 etapas; 1.000 subetapas; todos os estados iniciais pendentes.
A3: Subetapas | B3: Preencha estado e evidência. Concluída sem evidência não conta como verificada.
A4: Etapas | B4: Preencha responsável nominal, revisor, evidência do entregável e aceite validado.
A5: Conclusão | B5: A fórmula exige 10 subetapas verificadas e fechamento dos requisitos e dependências.
A6: Fórmulas | B6: O aplicativo de planilha recalcula ao abrir. A estrutura contém fórmulas em inglês no padrão XLSX.
A7: Revisão | B7: As fórmulas conferem preenchimento, não autenticidade de evidências ou identidade do revisor.
A8: Versões | B8: CSV e PDF são fotografias iniciais. Planilha e checklist HTML são registros independentes; escolha o registro oficial da equipe.
A9: Prazo | B9: Etapa não equivale a dia. Esforço e calendário dependem da etapa 10.
A10: Catálogo | B10: doufsxqlfjyuvxuezpln: somente consulta. Não escrever estoque, preço ou produto mestre.
A11: Banco próprio | B11: cfmzkthhgliqelozlmwu: operação do portal e snapshots históricos.
A12: Produção | B12: Conclusão do portal exige evidências de operação real conforme etapas 96–100.
A13: Referência | B13: Diagnóstico anterior e fontes técnicas na aba Referências.

Sheet Resumo
A1: Indicador | B1: Valor
A2: Etapas totais | B2: 100
A3: Subetapas totais | B3: 1000
A4: Subetapas verificadas | B4: =SUM(Subetapas!G2:G1001)
A5: Etapas concluídas | B5: =COUNTIF(Etapas!N2:N101,"Concluída")
A6: Avanço das subetapas | B6: =B4/B3
A7: Avanço das etapas | B7: =B5/B2
A8: Bloco | B8: Etapas concluídas
A9: Diagnóstico e estratégia | B9: =COUNTIFS(Etapas!B2:B101,A9,Etapas!N2:N101,"Concluída")
A10: Fundamentos e segurança | B10: =COUNTIFS(Etapas!B2:B101,A10,Etapas!N2:N101,"Concluída")
A11: Estrutura e conteúdo | B11: =COUNTIFS(Etapas!B2:B101,A11,Etapas!N2:N101,"Concluída")
A12: Sistema visual | B12: =COUNTIFS(Etapas!B2:B101,A12,Etapas!N2:N101,"Concluída")
A13: Catálogo e decisão | B13: =COUNTIFS(Etapas!B2:B101,A13,Etapas!N2:N101,"Concluída")
A14: Campanhas e propostas | B14: =COUNTIFS(Etapas!B2:B101,A14,Etapas!N2:N101,"Concluída")
A15: Governança e aprovações | B15: =COUNTIFS(Etapas!B2:B101,A15,Etapas!N2:N101,"Concluída")
A16: Execução e pós-compra | B16: =COUNTIFS(Etapas!B2:B101,A16,Etapas!N2:N101,"Concluída")
A17: Qualidade e validação | B17: =COUNTIFS(Etapas!B2:B101,A17,Etapas!N2:N101,"Concluída")
A18: Produção e expansão | B18: =COUNTIFS(Etapas!B2:B101,A18,Etapas!N2:N101,"Concluída")

Sheet Etapas
A1: Etapa | B1: Bloco | C1: Título | D1: Responsável funcional | E1: Dependências | F1: Entregável | G1: Critério obrigatório | H1: Subetapas verificadas | I1: Dependências concluídas | J1: Responsável nominal | K1: Revisor | L1: Evidência do entregável | M1: Aceite validado | N1: Estado calculado
A2: E001 | B2: Diagnóstico e estratégia | C2: Fixar o ponto de partida verificável | D2: Liderança técnica e Produto | E2: Nenhuma | F2: Inventário do ambiente e matriz de capacidades | G2: Cada capacidade possui origem, estado observado e responsável; produção não é inferida pelo README. | H2: =COUNTIFS(Subetapas!A$2:A$1001,A2,Subetapas!G$2:G$1001,1) | I2: =IF(TRUE,"Sim","Não") | M2: Não | N2: =IF(AND(H2=10,I2="Sim",LEN(TRIM(J2))>0,LEN(TRIM(K2))>0,LEN(TRIM(L2))>0,M2="Sim"),"Concluída",IF(H2=10,"Revisão ou dependências pendentes",IF(H2>0,"Em andamento","Pendente")))
A3: E002 | B3: Diagnóstico e estratégia | C3: Conter exposição de credenciais e ferramentas de teste | D3: Engenharia de segurança | E3: E001 | F3: Superfície de acesso emergencial corrigida | G3: Nenhuma função publicada devolve segredos; o tratamento da exposição potencial está documentado. | H3: =COUNTIFS(Subetapas!A$2:A$1001,A3,Subetapas!G$2:G$1001,1) | I3: =IF(AND(N2="Concluída"),"Sim","Não") | M3: Não | N3: =IF(AND(H3=10,I3="Sim",LEN(TRIM(J3))>0,LEN(TRIM(K3))>0,LEN(TRIM(L3))>0,M3="Sim"),"Concluída",IF(H3=10,"Revisão ou dependências pendentes",IF(H3>0,"Em andamento","Pendente")))
A4: E003 | B4: Diagnóstico e estratégia | C4: Garantir catálogo externo exclusivamente de consulta | D4: Engenharia de dados e Backend | E4: E001, E002 | F4: Contrato de integração somente leitura | G4: API e identidade de origem impedem gravações; amostra de leitura identifica corretamente o banco mestre. | H4: =COUNTIFS(Subetapas!A$2:A$1001,A4,Subetapas!G$2:G$1001,1) | I4: =IF(AND(N2="Concluída",N3="Concluída"),"Sim","Não") | M4: Não | N4: =IF(AND(H4=10,I4="Sim",LEN(TRIM(J4))>0,LEN(TRIM(K4))>0,LEN(TRIM(L4))>0,M4="Sim"),"Concluída",IF(H4=10,"Revisão ou dependências pendentes",IF(H4>0,"Em andamento","Pendente")))
A5: E004 | B5: Diagnóstico e estratégia | C5: Planejar pesquisa com compradores e marketing | D5: Pesquisa UX e Produto | E5: E001 | F5: Plano de pesquisa e recrutamento consentido | G5: Amostra cobre papéis e cooperativas distintas; observações são separadas de hipóteses. | H5: =COUNTIFS(Subetapas!A$2:A$1001,A5,Subetapas!G$2:G$1001,1) | I5: =IF(AND(N2="Concluída"),"Sim","Não") | M5: Não | N5: =IF(AND(H5=10,I5="Sim",LEN(TRIM(J5))>0,LEN(TRIM(K5))>0,LEN(TRIM(L5))>0,M5="Sim"),"Concluída",IF(H5=10,"Revisão ou dependências pendentes",IF(H5>0,"Em andamento","Pendente")))
A6: E005 | B6: Diagnóstico e estratégia | C6: Definir perfis funcionais e trabalhos a realizar | D6: Pesquisa UX e Estratégia | E6: E004 | F6: Perfis funcionais ligados a tarefas | G6: Cada perfil tem objetivo, contexto, dificuldade observada e critério de sucesso verificável. | H6: =COUNTIFS(Subetapas!A$2:A$1001,A6,Subetapas!G$2:G$1001,1) | I6: =IF(AND(N5="Concluída"),"Sim","Não") | M6: Não | N6: =IF(AND(H6=10,I6="Sim",LEN(TRIM(J6))>0,LEN(TRIM(K6))>0,LEN(TRIM(L6))>0,M6="Sim"),"Concluída",IF(H6=10,"Revisão ou dependências pendentes",IF(H6>0,"Em andamento","Pendente")))
A7: E006 | B7: Diagnóstico e estratégia | C7: Mapear a jornada atual e a jornada pretendida | D7: Estratégia de serviço e UX | E7: E004, E005 | F7: Mapas de jornada atual e futura | G7: Todas as passagens entre solicitação e recebimento têm ator, informação e dificuldade identificados. | H7: =COUNTIFS(Subetapas!A$2:A$1001,A7,Subetapas!G$2:G$1001,1) | I7: =IF(AND(N5="Concluída",N6="Concluída"),"Sim","Não") | M7: Não | N7: =IF(AND(H7=10,I7="Sim",LEN(TRIM(J7))>0,LEN(TRIM(K7))>0,LEN(TRIM(L7))>0,M7="Sim"),"Concluída",IF(H7=10,"Revisão ou dependências pendentes",IF(H7>0,"Em andamento","Pendente")))
A8: E007 | B8: Diagnóstico e estratégia | C8: Desenhar o serviço por trás da interface | D8: Estratégia de serviço e Operação | E8: E006 | F8: Mapa de serviço com responsabilidades | G8: Cada promessa exibida possui processo, sistema responsável e tratamento de falha. | H8: =COUNTIFS(Subetapas!A$2:A$1001,A8,Subetapas!G$2:G$1001,1) | I8: =IF(AND(N7="Concluída"),"Sim","Não") | M8: Não | N8: =IF(AND(H8=10,I8="Sim",LEN(TRIM(J8))>0,LEN(TRIM(K8))>0,LEN(TRIM(L8))>0,M8="Sim"),"Concluída",IF(H8=10,"Revisão ou dependências pendentes",IF(H8>0,"Em andamento","Pendente")))
A9: E008 | B9: Diagnóstico e estratégia | C9: Configurar governança por cooperativa | D9: Produto e responsáveis de compras | E9: E004, E007 | F9: Matriz de políticas locais versionadas | G9: Duas políticas distintas podem ser representadas sem criar regra nacional fictícia. | H9: =COUNTIFS(Subetapas!A$2:A$1001,A9,Subetapas!G$2:G$1001,1) | I9: =IF(AND(N5="Concluída",N8="Concluída"),"Sim","Não") | M9: Não | N9: =IF(AND(H9=10,I9="Sim",LEN(TRIM(J9))>0,LEN(TRIM(K9))>0,LEN(TRIM(L9))>0,M9="Sim"),"Concluída",IF(H9=10,"Revisão ou dependências pendentes",IF(H9>0,"Em andamento","Pendente")))
A10: E009 | B10: Diagnóstico e estratégia | C10: Definir resultados e instrumentos de medição | D10: Produto e Dados | E10: E005, E006 | F10: Dicionário inicial de indicadores | G10: Cada indicador tem evento de origem, denominador, período e limitação; ausência de medição é explícita. | H10: =COUNTIFS(Subetapas!A$2:A$1001,A10,Subetapas!G$2:G$1001,1) | I10: =IF(AND(N6="Concluída",N7="Concluída"),"Sim","Não") | M10: Não | N10: =IF(AND(H10=10,I10="Sim",LEN(TRIM(J10))>0,LEN(TRIM(K10))>0,LEN(TRIM(L10))>0,M10="Sim"),"Concluída",IF(H10=10,"Revisão ou dependências pendentes",IF(H10>0,"Em andamento","Pendente")))
A11: E010 | B11: Diagnóstico e estratégia | C11: Definir escopo e ordem das entregas | D11: Produto, UX e Liderança técnica | E11: E001, E005, E007, E008, E009 | F11: Plano de releases com critérios de saída | G11: Escopo preserva a jornada completa, explicita adiamentos e respeita dependências e capacidade. | H11: =COUNTIFS(Subetapas!A$2:A$1001,A11,Subetapas!G$2:G$1001,1) | I11: =IF(AND(N2="Concluída",N6="Concluída",N8="Concluída",N9="Concluída",N10="Concluída"),"Sim","Não") | M11: Não | N11: =IF(AND(H11=10,I11="Sim",LEN(TRIM(J11))>0,LEN(TRIM(K11))>0,LEN(TRIM(L11))>0,M11="Sim"),"Concluída",IF(H11=10,"Revisão ou dependências pendentes",IF(H11>0,"Em andamento","Pendente")))
A12: E011 | B12: Fundamentos e segurança | C12: Consolidar o modelo de dados do portal | D12: Backend e Arquitetura | E12: E003, E008, E010 | F12: Modelo canônico de entidades e contratos | G12: Nomes e vínculos de cooperativa, PA, verba e pedido são consistentes entre schema, serviços e telas. | H12: =COUNTIFS(Subetapas!A$2:A$1001,A12,Subetapas!G$2:G$1001,1) | I12: =IF(AND(N4="Concluída",N9="Concluída",N11="Concluída"),"Sim","Não") | M12: Não | N12: =IF(AND(H12=10,I12="Sim",LEN(TRIM(J12))>0,LEN(TRIM(K12))>0,LEN(TRIM(L12))>0,M12="Sim"),"Concluída",IF(H12=10,"Revisão ou dependências pendentes",IF(H12>0,"Em andamento","Pendente")))
A13: E012 | B13: Fundamentos e segurança | C13: Unificar permissões por ação e escopo | D13: Segurança e Backend | E13: E008, E011 | F13: Matriz de autorização implementável | G13: Permissões dependem de vínculo ativo e ação; cargo ou valor enviado pelo navegador não concedem acesso. | H13: =COUNTIFS(Subetapas!A$2:A$1001,A13,Subetapas!G$2:G$1001,1) | I13: =IF(AND(N9="Concluída",N12="Concluída"),"Sim","Não") | M13: Não | N13: =IF(AND(H13=10,I13="Sim",LEN(TRIM(J13))>0,LEN(TRIM(K13))>0,LEN(TRIM(L13))>0,M13="Sim"),"Concluída",IF(H13=10,"Revisão ou dependências pendentes",IF(H13>0,"Em andamento","Pendente")))
A14: E013 | B14: Fundamentos e segurança | C14: Implementar isolamento de dados e anexos | D14: Segurança e Backend | E14: E011, E012 | F14: Policies e testes entre organizações | G14: Usuários de cooperativas distintas não acessam registros, anexos ou funções fora de seu escopo. | H14: =COUNTIFS(Subetapas!A$2:A$1001,A14,Subetapas!G$2:G$1001,1) | I14: =IF(AND(N12="Concluída",N13="Concluída"),"Sim","Não") | M14: Não | N14: =IF(AND(H14=10,I14="Sim",LEN(TRIM(J14))>0,LEN(TRIM(K14))>0,LEN(TRIM(L14))>0,M14="Sim"),"Concluída",IF(H14=10,"Revisão ou dependências pendentes",IF(H14>0,"Em andamento","Pendente")))
A15: E014 | B15: Fundamentos e segurança | C15: Corrigir rotas e contrato de autenticação | D15: Frontend e QA | E15: E012, E013 | F15: Navegação autorizada por perfil | G15: Comprador, marketing e aprovador alcançam suas jornadas sem propriedades indefinidas ou barreiras contraditórias. | H15: =COUNTIFS(Subetapas!A$2:A$1001,A15,Subetapas!G$2:G$1001,1) | I15: =IF(AND(N13="Concluída",N14="Concluída"),"Sim","Não") | M15: Não | N15: =IF(AND(H15=10,I15="Sim",LEN(TRIM(J15))>0,LEN(TRIM(K15))>0,LEN(TRIM(L15))>0,M15="Sim"),"Concluída",IF(H15=10,"Revisão ou dependências pendentes",IF(H15>0,"Em andamento","Pendente")))
A16: E015 | B16: Fundamentos e segurança | C16: Definir autenticação confiável e acessível | D16: Segurança, Frontend e UX | E16: E002, E014 | F16: Fluxo técnico de entrada e recuperação | G16: Somente métodos realmente configurados aparecem; autenticação concluída corresponde a sessão válida. | H16: =COUNTIFS(Subetapas!A$2:A$1001,A16,Subetapas!G$2:G$1001,1) | I16: =IF(AND(N3="Concluída",N15="Concluída"),"Sim","Não") | M16: Não | N16: =IF(AND(H16=10,I16="Sim",LEN(TRIM(J16))>0,LEN(TRIM(K16))>0,LEN(TRIM(L16))>0,M16="Sim"),"Concluída",IF(H16=10,"Revisão ou dependências pendentes",IF(H16>0,"Em andamento","Pendente")))
A17: E016 | B17: Fundamentos e segurança | C17: Implementar convites e vínculos organizacionais | D17: Backend, UX e Administração | E17: E011, E012, E015 | F17: Onboarding controlado da cooperativa | G17: Convite cria apenas o vínculo autorizado; expiração, revogação e duplicidade possuem tratamento claro. | H17: =COUNTIFS(Subetapas!A$2:A$1001,A17,Subetapas!G$2:G$1001,1) | I17: =IF(AND(N12="Concluída",N13="Concluída",N16="Concluída"),"Sim","Não") | M17: Não | N17: =IF(AND(H17=10,I17="Sim",LEN(TRIM(J17))>0,LEN(TRIM(K17))>0,LEN(TRIM(L17))>0,M17="Sim"),"Concluída",IF(H17=10,"Revisão ou dependências pendentes",IF(H17>0,"Em andamento","Pendente")))
A18: E017 | B18: Fundamentos e segurança | C18: Tornar verba e compromissos consistentes | D18: Backend e Financeiro | E18: E008, E011, E012 | F18: Motor transacional de verba | G18: Concorrência e repetição não geram consumo duplicado nem saldo negativo fora da política autorizada. | H18: =COUNTIFS(Subetapas!A$2:A$1001,A18,Subetapas!G$2:G$1001,1) | I18: =IF(AND(N9="Concluída",N12="Concluída",N13="Concluída"),"Sim","Não") | M18: Não | N18: =IF(AND(H18=10,I18="Sim",LEN(TRIM(J18))>0,LEN(TRIM(K18))>0,LEN(TRIM(L18))>0,M18="Sim"),"Concluída",IF(H18=10,"Revisão ou dependências pendentes",IF(H18>0,"Em andamento","Pendente")))
A19: E018 | B19: Fundamentos e segurança | C19: Corrigir aprovação privilegiada no servidor | D19: Backend e Segurança | E19: E012, E013, E017 | F19: RPCs de decisão autorizadas e atômicas | G19: Ator, vínculo, alçada, versão e relação pedido/requisição são validados antes da decisão. | H19: =COUNTIFS(Subetapas!A$2:A$1001,A19,Subetapas!G$2:G$1001,1) | I19: =IF(AND(N13="Concluída",N14="Concluída",N18="Concluída"),"Sim","Não") | M19: Não | N19: =IF(AND(H19=10,I19="Sim",LEN(TRIM(J19))>0,LEN(TRIM(K19))>0,LEN(TRIM(L19))>0,M19="Sim"),"Concluída",IF(H19=10,"Revisão ou dependências pendentes",IF(H19>0,"Em andamento","Pendente")))
A20: E019 | B20: Fundamentos e segurança | C20: Restabelecer qualidade de build e testes | D20: Liderança técnica e QA | E20: E002, E003, E014, E018 | F20: Pipeline executável com resultados reais | G20: Gates críticos passam sem desativação; dívida remanescente possui inventário e não afeta a jornada liberada. | H20: =COUNTIFS(Subetapas!A$2:A$1001,A20,Subetapas!G$2:G$1001,1) | I20: =IF(AND(N3="Concluída",N4="Concluída",N15="Concluída",N19="Concluída"),"Sim","Não") | M20: Não | N20: =IF(AND(H20=10,I20="Sim",LEN(TRIM(J20))>0,LEN(TRIM(K20))>0,LEN(TRIM(L20))>0,M20="Sim"),"Concluída",IF(H20=10,"Revisão ou dependências pendentes",IF(H20>0,"Em andamento","Pendente")))
A21: E020 | B21: Fundamentos e segurança | C21: Preparar ambiente de validação e observabilidade | D21: Infraestrutura e Operação | E21: E001, E013, E019 | F21: Ambiente homologável e operação monitorada | G21: Saúde do catálogo e da compra pode ser observada; falhas têm alerta e responsável verificáveis. | H21: =COUNTIFS(Subetapas!A$2:A$1001,A21,Subetapas!G$2:G$1001,1) | I21: =IF(AND(N2="Concluída",N14="Concluída",N20="Concluída"),"Sim","Não") | M21: Não | N21: =IF(AND(H21=10,I21="Sim",LEN(TRIM(J21))>0,LEN(TRIM(K21))>0,LEN(TRIM(L21))>0,M21="Sim"),"Concluída",IF(H21=10,"Revisão ou dependências pendentes",IF(H21>0,"Em andamento","Pendente")))
A22: E021 | B22: Estrutura e conteúdo | C22: Organizar a arquitetura de informação | D22: UX e Conteúdo | E22: E005, E006, E010 | F22: Mapa de navegação por tarefa | G22: Participantes encontram catálogo, solicitações, aprovações e entregas sem depender de termos de vendedor. | H22: =COUNTIFS(Subetapas!A$2:A$1001,A22,Subetapas!G$2:G$1001,1) | I22: =IF(AND(N6="Concluída",N7="Concluída",N11="Concluída"),"Sim","Não") | M22: Não | N22: =IF(AND(H22=10,I22="Sim",LEN(TRIM(J22))>0,LEN(TRIM(K22))>0,LEN(TRIM(L22))>0,M22="Sim"),"Concluída",IF(H22=10,"Revisão ou dependências pendentes",IF(H22>0,"Em andamento","Pendente")))
A23: E022 | B23: Estrutura e conteúdo | C23: Construir taxonomia útil para brindes | D23: UX, Comercial e Dados | E23: E003, E005, E021 | F23: Taxonomia e mapeamento de atributos | G23: Categorias e atributos ajudam a decidir; valores desconhecidos não são apresentados como fatos. | H23: =COUNTIFS(Subetapas!A$2:A$1001,A23,Subetapas!G$2:G$1001,1) | I23: =IF(AND(N4="Concluída",N6="Concluída",N22="Concluída"),"Sim","Não") | M23: Não | N23: =IF(AND(H23=10,I23="Sim",LEN(TRIM(J23))>0,LEN(TRIM(K23))>0,LEN(TRIM(L23))>0,M23="Sim"),"Concluída",IF(H23=10,"Revisão ou dependências pendentes",IF(H23>0,"Em andamento","Pendente")))
A24: E023 | B24: Estrutura e conteúdo | C24: Projetar o comportamento da busca | D24: UX e Engenharia de busca | E24: E021, E022 | F24: Especificação de busca por nome, código e intenção | G24: Consultas prioritárias retornam opções pertinentes ou recuperação clara, sem inventar atributos. | H24: =COUNTIFS(Subetapas!A$2:A$1001,A24,Subetapas!G$2:G$1001,1) | I24: =IF(AND(N22="Concluída",N23="Concluída"),"Sim","Não") | M24: Não | N24: =IF(AND(H24=10,I24="Sim",LEN(TRIM(J24))>0,LEN(TRIM(K24))>0,LEN(TRIM(L24))>0,M24="Sim"),"Concluída",IF(H24=10,"Revisão ou dependências pendentes",IF(H24>0,"Em andamento","Pendente")))
A25: E024 | B25: Estrutura e conteúdo | C25: Projetar filtros e ordenação | D25: UX e Comercial | E25: E022, E023 | F25: Modelo de refinamento e ordenação | G25: Comprador entende critérios ativos, remove restrições e compara resultados sem perder contexto. | H25: =COUNTIFS(Subetapas!A$2:A$1001,A25,Subetapas!G$2:G$1001,1) | I25: =IF(AND(N23="Concluída",N24="Concluída"),"Sim","Não") | M25: Não | N25: =IF(AND(H25=10,I25="Sim",LEN(TRIM(J25))>0,LEN(TRIM(K25))>0,LEN(TRIM(L25))>0,M25="Sim"),"Concluída",IF(H25=10,"Revisão ou dependências pendentes",IF(H25>0,"Em andamento","Pendente")))
A26: E025 | B26: Estrutura e conteúdo | C26: Desenhar navegação entre cooperativas e unidades | D26: UX, Segurança e Frontend | E26: E012, E014, E016, E021 | F26: Padrão de contexto organizacional | G26: A unidade ativa é inequívoca; trocar contexto não transporta dados privados ou rascunhos incorretos. | H26: =COUNTIFS(Subetapas!A$2:A$1001,A26,Subetapas!G$2:G$1001,1) | I26: =IF(AND(N13="Concluída",N15="Concluída",N17="Concluída",N22="Concluída"),"Sim","Não") | M26: Não | N26: =IF(AND(H26=10,I26="Sim",LEN(TRIM(J26))>0,LEN(TRIM(K26))>0,LEN(TRIM(L26))>0,M26="Sim"),"Concluída",IF(H26=10,"Revisão ou dependências pendentes",IF(H26>0,"Em andamento","Pendente")))
A27: E026 | B27: Estrutura e conteúdo | C27: Estabelecer linguagem e conteúdo de interface | D27: Conteúdo UX e Produto | E27: E005, E008, E021 | F27: Guia de linguagem aplicado às jornadas | G27: Textos distinguem estimativa, aprovação, contratação e entrega sem promessas não comprovadas. | H27: =COUNTIFS(Subetapas!A$2:A$1001,A27,Subetapas!G$2:G$1001,1) | I27: =IF(AND(N6="Concluída",N9="Concluída",N22="Concluída"),"Sim","Não") | M27: Não | N27: =IF(AND(H27=10,I27="Sim",LEN(TRIM(J27))>0,LEN(TRIM(K27))>0,LEN(TRIM(L27))>0,M27="Sim"),"Concluída",IF(H27=10,"Revisão ou dependências pendentes",IF(H27>0,"Em andamento","Pendente")))
A28: E027 | B28: Estrutura e conteúdo | C28: Padronizar formulários e entrada de dados | D28: UX, Conteúdo e Frontend | E28: E011, E021, E026 | F28: Padrões de formulários com validação útil | G28: Campos solicitam apenas dados necessários; erros preservam valores e orientam correção. | H28: =COUNTIFS(Subetapas!A$2:A$1001,A28,Subetapas!G$2:G$1001,1) | I28: =IF(AND(N12="Concluída",N22="Concluída",N27="Concluída"),"Sim","Não") | M28: Não | N28: =IF(AND(H28=10,I28="Sim",LEN(TRIM(J28))>0,LEN(TRIM(K28))>0,LEN(TRIM(L28))>0,M28="Sim"),"Concluída",IF(H28=10,"Revisão ou dependências pendentes",IF(H28>0,"Em andamento","Pendente")))
A29: E028 | B29: Estrutura e conteúdo | C29: Definir estados vazios, falhas e recuperação | D29: UX, Frontend e Backend | E29: E003, E014, E026, E027 | F29: Catálogo de estados com comportamento real | G29: Cada falha oferece uma ação segura; carregamento e ausência de dados não ocultam indisponibilidade. | H29: =COUNTIFS(Subetapas!A$2:A$1001,A29,Subetapas!G$2:G$1001,1) | I29: =IF(AND(N4="Concluída",N15="Concluída",N27="Concluída",N28="Concluída"),"Sim","Não") | M29: Não | N29: =IF(AND(H29=10,I29="Sim",LEN(TRIM(J29))>0,LEN(TRIM(K29))>0,LEN(TRIM(L29))>0,M29="Sim"),"Concluída",IF(H29=10,"Revisão ou dependências pendentes",IF(H29>0,"Em andamento","Pendente")))
A30: E029 | B30: Estrutura e conteúdo | C30: Planejar avisos e notificações por evento | D30: UX, Operação e Backend | E30: E007, E009, E012, E026 | F30: Matriz de eventos, destinatários e canais | G30: Avisos têm destinatário autorizado e próxima ação; canal inexistente não é anunciado. | H30: =COUNTIFS(Subetapas!A$2:A$1001,A30,Subetapas!G$2:G$1001,1) | I30: =IF(AND(N8="Concluída",N10="Concluída",N13="Concluída",N27="Concluída"),"Sim","Não") | M30: Não | N30: =IF(AND(H30=10,I30="Sim",LEN(TRIM(J30))>0,LEN(TRIM(K30))>0,LEN(TRIM(L30))>0,M30="Sim"),"Concluída",IF(H30=10,"Revisão ou dependências pendentes",IF(H30>0,"Em andamento","Pendente")))
A31: E030 | B31: Estrutura e conteúdo | C31: Validar fluxos em protótipos de baixa fidelidade | D31: UX e Pesquisa | E31: E021, E023, E024, E025, E027, E028, E029 | F31: Fluxos testados antes do acabamento visual | G31: Tarefas críticas são compreendidas; problemas graves têm correção e nova verificação. | H31: =COUNTIFS(Subetapas!A$2:A$1001,A31,Subetapas!G$2:G$1001,1) | I31: =IF(AND(N22="Concluída",N24="Concluída",N25="Concluída",N26="Concluída",N28="Concluída",N29="Concluída",N30="Concluída"),"Sim","Não") | M31: Não | N31: =IF(AND(H31=10,I31="Sim",LEN(TRIM(J31))>0,LEN(TRIM(K31))>0,LEN(TRIM(L31))>0,M31="Sim"),"Concluída",IF(H31=10,"Revisão ou dependências pendentes",IF(H31>0,"Em andamento","Pendente")))
A32: E031 | B32: Sistema visual | C32: Definir direção visual com a marca Sicoob | D32: Direção de design e responsável pela marca | E32: E010, E026, E030 | F32: Direção visual e ativos autorizados | G32: A proposta usa a versão de marca validada e demonstra consistência em telas reais do portal. | H32: =COUNTIFS(Subetapas!A$2:A$1001,A32,Subetapas!G$2:G$1001,1) | I32: =IF(AND(N11="Concluída",N27="Concluída",N31="Concluída"),"Sim","Não") | M32: Não | N32: =IF(AND(H32=10,I32="Sim",LEN(TRIM(J32))>0,LEN(TRIM(K32))>0,LEN(TRIM(L32))>0,M32="Sim"),"Concluída",IF(H32=10,"Revisão ou dependências pendentes",IF(H32>0,"Em andamento","Pendente")))
A33: E032 | B33: Sistema visual | C33: Estabelecer grade, espaçamento e densidade | D33: Design de interface e Frontend | E33: E030, E031 | F33: Sistema de layout responsivo | G33: Páginas mantêm hierarquia e leitura em larguras pequenas, médias e amplas, sem medidas arbitrárias por tela. | H33: =COUNTIFS(Subetapas!A$2:A$1001,A33,Subetapas!G$2:G$1001,1) | I33: =IF(AND(N31="Concluída",N32="Concluída"),"Sim","Não") | M33: Não | N33: =IF(AND(H33=10,I33="Sim",LEN(TRIM(J33))>0,LEN(TRIM(K33))>0,LEN(TRIM(L33))>0,M33="Sim"),"Concluída",IF(H33=10,"Revisão ou dependências pendentes",IF(H33>0,"Em andamento","Pendente")))
A34: E033 | B34: Sistema visual | C34: Definir tipografia e hierarquia de leitura | D34: Design de interface e Conteúdo | E34: E026, E031, E032 | F34: Escala tipográfica aplicada | G34: Textos, valores e estados são legíveis; carregamento de fontes não prejudica a tarefa. | H34: =COUNTIFS(Subetapas!A$2:A$1001,A34,Subetapas!G$2:G$1001,1) | I34: =IF(AND(N27="Concluída",N32="Concluída",N33="Concluída"),"Sim","Não") | M34: Não | N34: =IF(AND(H34=10,I34="Sim",LEN(TRIM(J34))>0,LEN(TRIM(K34))>0,LEN(TRIM(L34))>0,M34="Sim"),"Concluída",IF(H34=10,"Revisão ou dependências pendentes",IF(H34>0,"Em andamento","Pendente")))
A35: E034 | B35: Sistema visual | C35: Definir cores semânticas e contraste | D35: Design de interface e Acessibilidade | E35: E031, E033 | F35: Paleta semântica acessível | G35: Combinações de texto e controles atendem os critérios aplicáveis; estado nunca depende apenas de cor. | H35: =COUNTIFS(Subetapas!A$2:A$1001,A35,Subetapas!G$2:G$1001,1) | I35: =IF(AND(N32="Concluída",N34="Concluída"),"Sim","Não") | M35: Não | N35: =IF(AND(H35=10,I35="Sim",LEN(TRIM(J35))>0,LEN(TRIM(K35))>0,LEN(TRIM(L35))>0,M35="Sim"),"Concluída",IF(H35=10,"Revisão ou dependências pendentes",IF(H35>0,"Em andamento","Pendente")))
A36: E035 | B36: Sistema visual | C36: Padronizar imagens, ícones e representação de produto | D36: Design e Conteúdo de catálogo | E36: E022, E031, E034 | F36: Guia de ativos visuais comerciais | G36: Imagens ajudam a avaliar o produto e distinguem fotografia, simulação e prova de produção. | H36: =COUNTIFS(Subetapas!A$2:A$1001,A36,Subetapas!G$2:G$1001,1) | I36: =IF(AND(N23="Concluída",N32="Concluída",N35="Concluída"),"Sim","Não") | M36: Não | N36: =IF(AND(H36=10,I36="Sim",LEN(TRIM(J36))>0,LEN(TRIM(K36))>0,LEN(TRIM(L36))>0,M36="Sim"),"Concluída",IF(H36=10,"Revisão ou dependências pendentes",IF(H36>0,"Em andamento","Pendente")))
A37: E036 | B37: Sistema visual | C37: Implementar tokens de design | D37: Frontend e Design de sistemas | E37: E032, E033, E034, E035 | F37: Tokens compartilhados entre especificação e código | G37: Mudança de um token atualiza os componentes correspondentes sem divergência visual ou semântica. | H37: =COUNTIFS(Subetapas!A$2:A$1001,A37,Subetapas!G$2:G$1001,1) | I37: =IF(AND(N33="Concluída",N34="Concluída",N35="Concluída",N36="Concluída"),"Sim","Não") | M37: Não | N37: =IF(AND(H37=10,I37="Sim",LEN(TRIM(J37))>0,LEN(TRIM(K37))>0,LEN(TRIM(L37))>0,M37="Sim"),"Concluída",IF(H37=10,"Revisão ou dependências pendentes",IF(H37>0,"Em andamento","Pendente")))
A38: E037 | B38: Sistema visual | C38: Consolidar componentes de ação e formulário | D38: Frontend, Design e Acessibilidade | E38: E027, E028, E036 | F38: Biblioteca essencial de interação | G38: Componentes possuem estados, semântica, foco e mensagens consistentes nas jornadas críticas. | H38: =COUNTIFS(Subetapas!A$2:A$1001,A38,Subetapas!G$2:G$1001,1) | I38: =IF(AND(N28="Concluída",N29="Concluída",N37="Concluída"),"Sim","Não") | M38: Não | N38: =IF(AND(H38=10,I38="Sim",LEN(TRIM(J38))>0,LEN(TRIM(K38))>0,LEN(TRIM(L38))>0,M38="Sim"),"Concluída",IF(H38=10,"Revisão ou dependências pendentes",IF(H38>0,"Em andamento","Pendente")))
A39: E038 | B39: Sistema visual | C39: Consolidar tabelas, listas e visualização de estados | D39: Frontend e Design | E39: E032, E033, E034, E036 | F39: Componentes de consulta operacional | G39: Dados densos continuam legíveis e operáveis, com seleção e paginação inequívocas. | H39: =COUNTIFS(Subetapas!A$2:A$1001,A39,Subetapas!G$2:G$1001,1) | I39: =IF(AND(N33="Concluída",N34="Concluída",N35="Concluída",N37="Concluída"),"Sim","Não") | M39: Não | N39: =IF(AND(H39=10,I39="Sim",LEN(TRIM(J39))>0,LEN(TRIM(K39))>0,LEN(TRIM(L39))>0,M39="Sim"),"Concluída",IF(H39=10,"Revisão ou dependências pendentes",IF(H39>0,"Em andamento","Pendente")))
A40: E039 | B40: Sistema visual | C40: Projetar feedback e movimento com propósito | D40: Design de interação e Frontend | E40: E028, E036, E037, E038 | F40: Padrão de transições e feedback | G40: Movimento orienta a tarefa, respeita redução de animação e não encobre confirmação operacional. | H40: =COUNTIFS(Subetapas!A$2:A$1001,A40,Subetapas!G$2:G$1001,1) | I40: =IF(AND(N29="Concluída",N37="Concluída",N38="Concluída",N39="Concluída"),"Sim","Não") | M40: Não | N40: =IF(AND(H40=10,I40="Sim",LEN(TRIM(J40))>0,LEN(TRIM(K40))>0,LEN(TRIM(L40))>0,M40="Sim"),"Concluída",IF(H40=10,"Revisão ou dependências pendentes",IF(H40>0,"Em andamento","Pendente")))
...

Sheet Subetapas
A1: Etapa | B1: ID da subetapa | C1: Ação obrigatória | D1: Responsável funcional | E1: Estado informado | F1: Evidência | G1: Verificada | H1: Data do registro
A2: E001 | B2: E001.01 | C2: Registrar o commit de referência e os links do diagnóstico anterior. | D2: Liderança técnica e Produto | E2: Pendente | G2: =IF(AND(E2="Concluída",LEN(TRIM(F2))>0),1,0)
A3: E001 | B3: E001.02 | C3: Identificar domínio produtivo, prévia e ambiente segregado de testes. | D3: Liderança técnica e Produto | E3: Pendente | G3: =IF(AND(E3="Concluída",LEN(TRIM(F3))>0),1,0)
A4: E001 | B4: E001.03 | C4: Confirmar os identificadores dos dois bancos com metadados seguros. | D4: Liderança técnica e Produto | E4: Pendente | G4: =IF(AND(E4="Concluída",LEN(TRIM(F4))>0),1,0)
A5: E001 | B5: E001.04 | C5: Relacionar funções publicadas com as funções presentes no repositório. | D5: Liderança técnica e Produto | E5: Pendente | G5: =IF(AND(E5="Concluída",LEN(TRIM(F5))>0),1,0)
A6: E001 | B6: E001.05 | C6: Classificar telas entre demonstradas, parcialmente funcionais e sem evidência. | D6: Liderança técnica e Produto | E6: Pendente | G6: =IF(AND(E6="Concluída",LEN(TRIM(F6))>0),1,0)
A7: E001 | B7: E001.06 | C7: Registrar os resultados reais de build, tipos e testes disponíveis. | D7: Liderança técnica e Produto | E7: Pendente | G7: =IF(AND(E7="Concluída",LEN(TRIM(F7))>0),1,0)
A8: E001 | B8: E001.07 | C8: Catalogar divergências entre documentação, configuração e comportamento observado. | D8: Liderança técnica e Produto | E8: Pendente | G8: =IF(AND(E8="Concluída",LEN(TRIM(F8))>0),1,0)
A9: E001 | B9: E001.08 | C9: Mapear responsáveis por produto, marca, compra, operação e infraestrutura. | D9: Liderança técnica e Produto | E9: Pendente | G9: =IF(AND(E9="Concluída",LEN(TRIM(F9))>0),1,0)
A10: E001 | B10: E001.09 | C10: Criar um registro de decisões com data, justificativa e impacto. | D10: Liderança técnica e Produto | E10: Pendente | G10: =IF(AND(E10="Concluída",LEN(TRIM(F10))>0),1,0)
A11: E001 | B11: E001.10 | C11: Revisar o inventário e anexar evidências de cada afirmação operacional. | D11: Liderança técnica e Produto | E11: Pendente | G11: =IF(AND(E11="Concluída",LEN(TRIM(F11))>0),1,0)
A12: E002 | B12: E002.01 | C12: Verificar por inventário seguro se migrate-helper está publicado. | D12: Engenharia de segurança | E12: Pendente | G12: =IF(AND(E12="Concluída",LEN(TRIM(F12))>0),1,0)
A13: E002 | B13: E002.02 | C13: Inspecionar a configuração de autorização sem invocar retorno de segredos. | D13: Engenharia de segurança | E13: Pendente | G13: =IF(AND(E13="Concluída",LEN(TRIM(F13))>0),1,0)
... A1001: E100 | B1001: E100.10 | C1001: Registrar o aceite final da implantação com responsáveis, data e evidências verificáveis. | D1001: Produto, Design, Engenharia e Operação | E1001: Pendente | G1001: =IF(AND(E1001="Concluída",LEN(TRIM(F1001))>0),1,0)

Sheet Referências
A1: ID | B1: Título | C1: Origem | D1: URL | E1: Aplicação e limite
A2: R01 | B2: Diagnóstico do portal Sicoob e anexos | C2: Pesquisa do projeto, 11/09/2026 | D2: https://github.com/adm01-debug/Brindes_Sicoob_V2/blob/ec5cfaf5c2de844458c0105d8ad40c35f1eb9c14/docs/pesquisa/2026-09-11/dossie.md | E2: Reaproveitamento, riscos, políticas locais e perfis funcionais; não certifica produção.
A3: R02 | B3: Guia da marca Sicoob | C3: Março/2023; versão vigente a confirmar | D3: https://portalcredicope.com.br/uploads/DOCUMENTOS/GUIA_DA_MARCA_-SICOOB_marco_23.pdf | E3: Direção visual; a etapa 31 exige validação atual dos ativos e da especificação.
A4: R03 | B4: Heurísticas de usabilidade de Jakob Nielsen | C4: NN/g; revisão de 30/01/2024 | D4: https://www.nngroup.com/articles/ten-usability-heuristics/ | E4: Revisão de clareza, consistência, controle, prevenção e recuperação de erros.
A5: R04 | B5: WCAG 2.2 | C5: W3C; referência normativa consultada em 11/09/2026 | D5: https://www.w3.org/TR/WCAG22/ | E5: Meta de conformidade AA; exige verificar todos os critérios aplicáveis, não apenas automação.
A6: R05 | B6: Contraste mínimo de texto | C6: W3C WAI; consultado em 11/09/2026 | D6: https://www.w3.org/WAI/WCAG22/Understanding/contrast-minimum | E6: 4,5:1 para texto normal e 3:1 para texto grande, com exceções normativas.
A7: R06 | B7: Contraste de informação não textual | C7: W3C WAI; consultado em 11/09/2026 | D7: https://www.w3.org/WAI/WCAG22/Understanding/non-text-contrast.html | E7: Verificação de informação visual essencial de controles e gráficos.
A8: R07 | B8: Tamanho mínimo de alvo de interação | C8: W3C WAI; consultado em 11/09/2026 | D8: https://www.w3.org/WAI/WCAG22/Understanding/target-size-minimum | E8: Mínimo de 24 × 24 CSS px ou condições de exceção; 44 px é preferência proposta para ações principais.
A9: R08 | B9: Foco não encoberto | C9: W3C WAI; consultado em 11/09/2026 | D9: https://www.w3.org/WAI/WCAG22/Understanding/focus-not-obscured-minimum.html | E9: Evitar que conteúdo fixo esconda o componente com foco, observadas as condições do critério.
A10: R09 | B10: Web Vitals | C10: Google web.dev; consultado em 11/09/2026 | D10: https://web.dev/articles/vitals | E10: Referências de campo: LCP 2,5 s, INP 200 ms e CLS 0,1 no percentil 75; laboratório é outra evidência.
A11: R10 | B11: Concluir múltiplas tarefas | C11: GOV.UK Design System; consultado em 11/09/2026 | D11: https://design-system.service.gov.uk/patterns/complete-multiple-tasks/ | E11: Organização de tarefas e estados; aplicação adaptada às jornadas institucionais do portal.
